<?xml version="1.0"?>
<robot xmlns:xacro="http://wiki.ros.org/xacro" name="ur_gripper">

	<!-- Arbitrary offsets for shoulder/elbow joints -->
	<xacro:property name="shoulder_offset" value="0.13585" />
	<xacro:property name="elbow_offset" value="0.1197" />

	<!-- Inertia parameters -->
	<xacro:property name="base_mass" value="4.0" />
	<xacro:property name="shoulder_mass" value="3.7000" />
	<xacro:property name="upper_arm_mass" value="8.3930" />
	<xacro:property name="forearm_mass" value="2.2750" />
	<xacro:property name="wrist_1_mass" value="1.2190" />
	<xacro:property name="wrist_2_mass" value="1.2190" />
	<xacro:property name="wrist_3_mass" value="0.1879" />

	<!-- link lengths used in model -->
	<xacro:property name="shoulder_height" value="0.089159" />
	<xacro:property name="upper_arm_length" value="0.42500" />
	<xacro:property name="forearm_length" value="0.39225" />
	<xacro:property name="wrist_1_length" value="0.093" />
	<xacro:property name="wrist_2_length" value="0.09465" />
	<xacro:property name="wrist_3_length" value="0.0823" />

	<!-- link radi used in model -->
	<xacro:property name="shoulder_radius" value="0.060" />
	<xacro:property name="upper_arm_radius" value="0.054" />
	<xacro:property name="elbow_radius" value="0.060" />
	<xacro:property name="forearm_radius" value="0.040" />
	<xacro:property name="wrist_radius" value="0.045" />
	<xacro:property name="box_dim" value="0.140" />

	<xacro:macro name="cylinder_inertial" params="radius length mass">
		<inertial>
			<mass value="${mass}" />
			<origin xyz="0 0 0" rpy="0 0 0" />
			<inertia 
				ixx="${0.0833333*mass*(3*radius*radius + length*length)}"
				ixy="0.0" ixz="0.0"
			    	iyy="${0.0833333*mass*(3*radius*radius + length*length)}" iyz="0.0"
		    		izz="${0.5*mass*radius*radius}"
			/>
	   	</inertial>
	</xacro:macro>

	<xacro:macro name="generic_link" params="name radius length mass visual_mesh collision_mesh">
		<link name="${name}">
			<xacro:cylinder_inertial radius="${radius}" length="${length}" mass="${mass}"/>
			<visual>
				<geometry>
					<mesh filename="${visual_mesh}"/>
				</geometry>
			</visual>
			<collision>
				<geometry>
					<mesh filename="${collision_mesh}"/>
				</geometry>
			</collision>
		</link>
	</xacro:macro>

	<xacro:macro name="ur_joint" params="name parent child *origin *axis">
		<joint name="${name}" type="revolute">
		    <xacro:insert_block name="origin" />
		    <xacro:insert_block name="axis" />
		    <limit lower="-3.1416" upper="3.1416" effort="150" velocity="3.1416" />
		    <child link="${child}" />
		    <parent link="${parent}" />
		</joint>
	</xacro:macro>


	<xacro:macro name="ur5_macro">

		<xacro:generic_link name="urbase_link" radius="0" length="0"
			mass="${shoulder_mass}" visual_mesh="package://ur_description/meshes/ur5/visual/base.dae"
			collision_mesh="package://ur_description/meshes/ur5/collision/base.stl"/>

		<xacro:generic_link name="shoulder_link" radius="${shoulder_radius}" length="${shoulder_height}"
			mass="${shoulder_mass}" visual_mesh="package://ur_description/meshes/ur5/visual/shoulder.dae"
			collision_mesh="package://ur_description/meshes/ur5/collision/shoulder.stl"
		/>

		<xacro:generic_link name="upper_arm_link" radius="${upper_arm_radius}" length="${upper_arm_length}"
			mass="${upper_arm_mass}" visual_mesh="package://ur_description/meshes/ur5/visual/upperarm.dae"
			collision_mesh="package://ur_description/meshes/ur5/collision/upperarm.stl"
		/>

		<xacro:generic_link name="forearm_link" radius="${forearm_radius}" length="${forearm_length}"
			mass="${forearm_mass}" visual_mesh="package://ur_description/meshes/ur5/visual/forearm.dae"
			collision_mesh="package://ur_description/meshes/ur5/collision/forearm.stl"
		/>

		<xacro:generic_link name="wrist_1_link" radius="${wrist_radius}" length="${wrist_1_length}"
			mass="${wrist_1_mass}" visual_mesh="package://ur_description/meshes/ur5/visual/wrist1.dae"
			collision_mesh="package://ur_description/meshes/ur5/collision/wrist1.stl"
		/>

		<xacro:generic_link name="wrist_2_link" radius="${wrist_radius}" length="${wrist_2_length}"
			mass="${wrist_2_mass}" visual_mesh="package://ur_description/meshes/ur5/visual/wrist2.dae"
			collision_mesh="package://ur_description/meshes/ur5/collision/wrist2.stl"
		/>

		<xacro:generic_link name="wrist_3_link" radius="${wrist_radius}" length="${wrist_3_length}"
			mass="${wrist_3_mass}" visual_mesh="package://ur_description/meshes/ur5/visual/wrist3.dae"
			collision_mesh="package://ur_description/meshes/ur5/collision/wrist3.stl"
		/>

		<xacro:ur_joint name="urbase_joint" parent="urbase_link" child="shoulder_link">
			<origin xyz="0 0 ${shoulder_height}" rpy="0 0 0"/>
			<axis xyz="0 0 1"/>
		</xacro:ur_joint>

		<xacro:ur_joint name="shoulder" parent="shoulder_link" child="upper_arm_link">
			<origin xyz="0 ${shoulder_offset} 0" rpy="0 0 0"/>
			<axis xyz="0 1 0"/>
		</xacro:ur_joint>

		<xacro:ur_joint name="elbow" parent="upper_arm_link" child="forearm_link">
			<origin xyz="0 ${-elbow_offset} ${upper_arm_length}" rpy="0 0 0"/>
			<axis xyz="0 1 0"/>
		</xacro:ur_joint>

		<xacro:ur_joint name="wrist_1" parent="forearm_link" child="wrist_1_link">
			<origin xyz="0 0 ${forearm_length}" rpy="0 0 0"/>
			<axis xyz="0 1 0"/>
		</xacro:ur_joint>

		<xacro:ur_joint name="wrist_2" parent="wrist_1_link" child="wrist_2_link">
			<origin xyz="0 ${wrist_1_length} 0" rpy="0 0 0"/>
			<axis xyz="0 0 1"/>
		</xacro:ur_joint>

		<xacro:ur_joint name="wrist_3" parent="wrist_2_link" child="wrist_3_link">
			<origin xyz="0 0 ${wrist_2_length}" rpy="0 0 0"/>
			<axis xyz="0 1 0"/>
		</xacro:ur_joint>
		
	</xacro:macro>

</robot>

