<?xml version="1.0" encoding="utf-8"?>
<!-- =================================================================================== -->
<!-- |    This document was autogenerated by xacro from ur5.urdf.xacro                 | -->
<!-- |    EDITING THIS FILE BY HAND IS NOT RECOMMENDED                                 | -->
<!-- =================================================================================== -->
<robot name="ur5_test">
  <!-- measured from model -->
  <!-- manually measured -->
  <!-- proposed -->
  <!-- Links -->
  <link name="base_link">
    <visual>
      <geometry>
        <mesh filename="package://ur_description/meshes/ur5/visual/base.dae"/>
      </geometry>
      <origin rpy="0 0 0" xyz="0 0 0"/>
      <material name="Gray">
        <color rgba="0.8 0.8 0.8 1.0"/>
      </material>
    </visual>
  </link>
  <link name="square_base">
    <inertial>
      <mass value="3.7"/>
      <inertia ixx="0.00578104026589" ixy="0.0" ixz="0.0" iyy="0.00578104026589" iyz="0.0" izz="0.00666"/>
    </inertial>
    <visual>
      <geometry>
        <mesh filename="package://ur_description/meshes/ur5/visual/shoulder.dae"/>
      </geometry>
      <origin rpy="0 0 0" xyz="0 0 0"/>
      <material name="Gray">
        <color rgba="0.8 0.8 0.8 1.0"/>
      </material>
    </visual>
  </link>
  <link name="upper_arm_link">
    <inertial>
      <mass value="8.393"/>
      <inertia ixx="0.132450579436" ixy="0.0" ixz="0.0" iyy="0.132450579436" iyz="0.0" izz="0.012236994"/>
    </inertial>
    <visual>
      <geometry>
        <mesh filename="package://ur_description/meshes/ur5/visual/upperarm.dae"/>
      </geometry>
      <origin rpy="0 0 0" xyz="0 0 0"/>
      <material name="Gray">
        <color rgba="0.8 0.8 0.8 1.0"/>
      </material>
    </visual>
  </link>
  <link name="forearm_link">
    <inertial>
      <mass value="2.275"/>
      <inertia ixx="0.0300792914839" ixy="0.0" ixz="0.0" iyy="0.0300792914839" iyz="0.0" izz="0.00182"/>
    </inertial>
    <visual>
      <geometry>
        <mesh filename="package://ur_description/meshes/ur5/visual/forearm.dae"/>
      </geometry>
      <origin rpy="0 0 0" xyz="0 0 0"/>
      <material name="Gray">
        <color rgba="0.8 0.8 0.8 1.0"/>
      </material>
    </visual>
  </link>
  <link name="wrist_1_link">
    <inertial>
      <mass value="1.219"/>
      <inertia ixx="0.00149571240171" ixy="0.0" ixz="0.0" iyy="0.00149571240171" iyz="0.0" izz="0.0012342375"/>
    </inertial>
    <visual>
      <geometry>
        <mesh filename="package://ur_description/meshes/ur5/visual/wrist1.dae"/>
      </geometry>
      <origin rpy="0 0 0" xyz="0 0 0"/>
      <material name="Gray">
        <color rgba="0.8 0.8 0.8 1.0"/>
      </material>
    </visual>
  </link>
  <link name="wrist_2_link">
    <inertial>
      <mass value="1.219"/>
      <inertia ixx="0.00152716487476" ixy="0.0" ixz="0.0" iyy="0.00152716487476" iyz="0.0" izz="0.0012342375"/>
    </inertial>
    <visual>
      <geometry>
        <mesh filename="package://ur_description/meshes/ur5/visual/wrist2.dae"/>
      </geometry>
      <origin rpy="0 0 0" xyz="0 0 0"/>
      <material name="Gray">
        <color rgba="0.8 0.8 0.8 1.0"/>
      </material>
    </visual>
  </link>
  <link name="wrist_3_link">
    <inertial>
      <mass value="0.1879"/>
      <inertia ixx="0.00020118272711" ixy="0.0" ixz="0.0" iyy="0.00020118272711" iyz="0.0" izz="0.00019024875"/>
    </inertial>
    <visual>
      <geometry>
        <mesh filename="package://ur_description/meshes/ur5/visual/wrist3.dae"/>
      </geometry>
      <origin rpy="0 0 0" xyz="0 0 0"/>
      <material name="Gray">
        <color rgba="0.8 0.8 0.8 1.0"/>
      </material>
    </visual>
  </link>
  <joint name="base" type="revolute">
    <origin rpy="0 0 0" xyz="0 0 0.089159"/>
    <axis xyz="0 0 1"/>
    <limit effort="150" lower="-3.1416" upper="3.1416" velocity="3.1416"/>
    <child link="square_base"/>
    <parent link="base_link"/>
  </joint>
  <joint name="shoulder" type="revolute">
    <origin rpy="0 0 0" xyz="0 0.13585 0"/>
    <axis xyz="0 1 0"/>
    <limit effort="150" lower="-3.1416" upper="3.1416" velocity="3.1416"/>
    <child link="upper_arm_link"/>
    <parent link="square_base"/>
  </joint>
  <joint name="elbow" type="revolute">
    <origin rpy="0 0 0" xyz="0 -0.1197 0.425"/>
    <axis xyz="0 1 0"/>
    <limit effort="150" lower="-3.1416" upper="3.1416" velocity="3.1416"/>
    <child link="forearm_link"/>
    <parent link="upper_arm_link"/>
  </joint>
  <joint name="wrist_1" type="revolute">
    <origin rpy="0 0 0" xyz="0 0 0.39225"/>
    <axis xyz="0 1 0"/>
    <limit effort="150" lower="-3.1416" upper="3.1416" velocity="3.1416"/>
    <child link="wrist_1_link"/>
    <parent link="forearm_link"/>
  </joint>
  <joint name="wrist_2" type="revolute">
    <origin rpy="0 0 0" xyz="0 0.093 0"/>
    <axis xyz="0 0 1"/>
    <limit effort="150" lower="-3.1416" upper="3.1416" velocity="3.1416"/>
    <child link="wrist_2_link"/>
    <parent link="wrist_1_link"/>
  </joint>
  <joint name="wrist_3" type="revolute">
    <origin rpy="0 0 0" xyz="0 0 0.09465"/>
    <axis xyz="0 1 0"/>
    <limit effort="150" lower="-3.1416" upper="3.1416" velocity="3.1416"/>
    <child link="wrist_3_link"/>
    <parent link="wrist_2_link"/>
  </joint>
</robot>

