<?xml version="1.0"?>
<robot xmlns:xacro="http://ros.org/wiki/xacro" name="ur5_test" >

    <!-- Arbitrary offsets for shoulder/elbow joints -->
    <!-- shoulder_offset - elbow_offset + wrist_1_length = 0.10915 -->
    <xacro:property name="shoulder_offset" value="0.13585" />  <!-- measured from model -->
    <xacro:property name="elbow_offset" value="0.1197" /> <!-- measured from model -->
    
    <!-- Inertia parameters -->
    <xacro:property name="base_mass" value="4.0" />  <!-- This mass might be incorrect -->
    <xacro:property name="shoulder_mass" value="3.7000" />
    <xacro:property name="upper_arm_mass" value="8.3930" />
    <xacro:property name="forearm_mass" value="2.2750" />
    <xacro:property name="wrist_1_mass" value="1.2190" />
    <xacro:property name="wrist_2_mass" value="1.2190" />
    <xacro:property name="wrist_3_mass" value="0.1879" />

    <!-- link lengths used in model -->
    <xacro:property name="shoulder_height" value="0.089159" />
    <xacro:property name="upper_arm_length" value="0.42500" />
    <xacro:property name="forearm_length" value="0.39225" />
    <xacro:property name="wrist_1_length" value="0.093" />    <!-- CAD measured -->
    <xacro:property name="wrist_2_length" value="0.09465" />    <!-- In CAD this distance is 0.930, but in the spec it is 0.09465 -->
    <xacro:property name="wrist_3_length" value="0.0823" />

    <xacro:property name="shoulder_radius" value="0.060" />   <!-- manually measured -->
    <xacro:property name="upper_arm_radius" value="0.054" />  <!-- manually measured -->
    <xacro:property name="elbow_radius" value="0.060" />      <!-- manually measured -->
    <xacro:property name="forearm_radius" value="0.040" />    <!-- manually measured -->
    <xacro:property name="wrist_radius" value="0.045" />      <!-- manually measured -->
    
    <xacro:property name="box_dim" value="0.140" />      <!-- proposed -->
    
    <!-- Helper macros -->
    <xacro:macro name="inertial_macro" params="radius length mass">
        <inertial>
            <mass value="${mass}" />
            <inertia 	ixx="${0.0833333 * mass * (3 * radius * radius + length * length)}" ixy="0.0" ixz="0.0"
                iyy="${0.0833333 * mass * (3 * radius * radius + length * length)}" iyz="0.0"
                izz="${0.5 * mass * radius * radius}" />
        </inertial>
    </xacro:macro>

    <!-- Macro for links -->
    <xacro:macro name="generic_link" params="name radius length mass filename">
		<link name="${name}">
			<xacro:inertial_macro radius="${radius}" length="${length}" mass="${mass}"/>
			<visual>
            	<geometry>
            	    <mesh filename="${filename}"/>
        		</geometry>
			</visual>
        </link>
    </xacro:macro>
    
    <!-- Macro for joints -->
    <xacro:macro name="ur_joint" params="name parent child *origin *axis">
        <joint name="${name}" type="revolute">
            <xacro:insert_block name="origin" />
            <xacro:insert_block name="axis" />
            <limit lower="-3.1416" upper="3.1416" effort="150" velocity="3.1416" />
            <child link="${child}" />
            <parent link="${parent}" />
        </joint>
    </xacro:macro>
    
    <!-- Links -->
    <link name="base_link" >
    </link>

    <xacro:generic_link name="square_base" radius="${shoulder_radius}" length="${shoulder_height}"
        mass="${shoulder_mass}" filename="package://ur_description/meshes/ur5/visual/shoulder.dae" >
    </xacro:generic_link>

    <xacro:generic_link name="upper_arm_link" radius="${upper_arm_radius}" length="${upper_arm_length}"
        mass="${upper_arm_mass}" filename="package://ur_description/meshes/ur5/visual/upperarm.dae" >
    </xacro:generic_link>

    <xacro:generic_link name="forearm_link" radius="${forearm_radius}" length="${forearm_length}"
        mass="${forearm_mass}" filename="package://ur_description/meshes/ur5/visual/forearm.dae" >
    </xacro:generic_link>

    <xacro:generic_link name="wrist_1_link" radius="${wrist_radius}" length="${wrist_1_length}"
        mass="${wrist_1_mass}" filename="package://ur_description/meshes/ur5/visual/wrist1.dae" >
    </xacro:generic_link>

    <xacro:generic_link name="wrist_2_link" radius="${wrist_radius}" length="${wrist_2_length}"
        mass="${wrist_2_mass}" filename="package://ur_description/meshes/ur5/visual/wrist2.dae" >
    </xacro:generic_link>

    <xacro:generic_link name="wrist_3_link" radius="${wrist_radius}" length="${wrist_3_length}"
        mass="${wrist_3_mass}" filename="package://ur_description/meshes/ur5/visual/wrist3.dae" >
    </xacro:generic_link>
    
    <!-- Joints -->
    <xacro:ur_joint name="base" parent="base_link" child="square_base">
        <origin xyz="0 0 ${shoulder_height}" rpy="0 0 0"/>
        <axis xyz="0 0 1"/>
    </xacro:ur_joint>
    
    <xacro:ur_joint name="shoulder" parent="square_base" child="upper_arm_link">
        <origin xyz="0 ${shoulder_offset} 0" rpy="0 0 0"/>
        <axis xyz="0 1 0"/>
    </xacro:ur_joint>

    <xacro:ur_joint name="elbow" parent="upper_arm_link" child="forearm_link">
        <origin xyz="0 ${-elbow_offset} ${upper_arm_length}" rpy="0 0 0"/>
        <axis xyz="0 1 0"/>
    </xacro:ur_joint>

    <xacro:ur_joint name="wrist_1" parent="forearm_link" child="wrist_1_link">
        <origin xyz="0 0 ${forearm_length}" rpy="0 0 0"/>
        <axis xyz="0 1 0"/>
    </xacro:ur_joint>

    <xacro:ur_joint name="wrist_2" parent="wrist_1_link" child="wrist_2_link">
        <origin xyz="0 ${wrist_1_length} 0" rpy="0 0 0"/>
        <axis xyz="0 0 1"/>
    </xacro:ur_joint>
    
    <xacro:ur_joint name="wrist_3" parent="wrist_2_link" child="wrist_3_link">
        <origin xyz="0 0 ${wrist_2_length}" rpy="0 0 0"/>
        <axis xyz="0 1 0"/>
    </xacro:ur_joint>
    
</robot>
